<?xml version="1.0" ?>
<robot name="right-pull-door">
	<link name="base"/>
	<link name="link_0">
		<visual name="out-frame">
			<origin xyz="0 0 0"/>
			<geometry>
				<mesh filename="texture_dae/frame.dae" scale="0.7256157167437052 0.7256157167437052 0.7256157167437052"/>
			</geometry>
		</visual>
		<collision>
			<origin xyz="0 0 0"/>
			<geometry>
				<mesh filename="texture_dae/frame.dae" scale="0.7256157167437052 0.7256157167437052 0.7256157167437052"/>
			</geometry>
		</collision>
	</link>
	<joint name="joint_0" type="fixed">
		<origin rpy="1.570796326794897 0 -1.570796326794897" xyz="0 0 0"/>
		<child link="link_0"/>
		<parent link="base"/>
	</joint>
	<link name="link_1">
		<visual name="surf-board">
			<origin xyz="0.2897215559504412 -0.8330896486361368 0"/>
			<geometry>
				<mesh filename="texture_dae/board.dae" scale="0.7256157167437052 0.7256157167437052 0.7256157167437052"/>
			</geometry>
		</visual>
		<collision>
			<origin xyz="0.2897215559504412 -0.8330896486361368 0"/>
			<geometry>
				<mesh filename="texture_dae/board.dae" scale="0.7256157167437052 0.7256157167437052 0.7256157167437052"/>
			</geometry>
		</collision>
	</link>
	<joint name="joint_1" type="revolute">
		<origin xyz="-0.2897215559504412 0.8330896486361368 0"/>
		<axis xyz="0 -1 0"/>
		<child link="link_1"/>
		<parent link="link_0"/>
		<limit lower="0" upper="1.5079644737231006"/>
	</joint>
	<link name="link_2">
		<visual name="handle">
			<origin xyz="0 0 0"/>
			<geometry>
				<mesh filename="texture_dae/9960006.dae" scale="2.0909242239296537 2.0909242239296537 2.0909242239296537"/>
			</geometry>
		</visual>
		<collision>
			<origin xyz="0 0 0"/>
			<geometry>
				<mesh filename="texture_dae/9960006.dae" scale="2.0909242239296537 2.0909242239296537 2.0909242239296537"/>
			</geometry>
		</collision>
	</link>
	<joint name="joint_2" type="revolute">
		<origin xyz="0.5004925182481696 -0.9411824802108322 0.027711846456493213"/>
		<child link="link_2"/>
		<parent link="link_1"/>
		<axis xyz="0 0 1"/>
		<limit lower="0" upper="1.5079644737231006"/>
	</joint>
</robot>
