<?xml version='1.0' encoding='utf-8'?>
<robot name="a2wz1">
  <mujoco>
    <compiler meshdir="../meshes" discardvisual="false" />
  </mujoco>
  <link name="world" />
  <joint name="floating_base_joint" type="floating">
    <parent link="world" />
    <child link="base_link" />
  </joint>
  <link name="base_link">
    <inertial>
      <origin xyz="6.982591E-03 -0.712858E-03 12.889523E-03" rpy="0 0 0" />
      <mass value="19.651" />
      <inertia ixx="141775.328248061E-06" ixy="400.505020171E-06" ixz="-6996.487718114E-06" iyy="407724.601564754E-06" iyz="-361.858857563E-06" izz="472247.985516800E-06" />
    </inertial>
    <visual>
      <origin xyz="0 0 0" rpy="0 0 0" />
      <geometry>
        <mesh filename="../meshes/base_link.STL" />
      </geometry>
      <material name="">
        <color rgba="0.792156862745098 0.819607843137255 0.933333333333333 1" />
      </material>
    </visual>
    <collision>
      <origin xyz="0 0 0.01" rpy="0 0 0" />
      <geometry>
        <box size="0.24 0.28 0.16" />
      </geometry>
    </collision>
  </link>
  <link name="front_bumper">
    <inertial>
      <origin xyz="0 0 0" rpy="0 0 0" />
      <mass value="0.01" />
      <inertia ixx="0.001" ixy="0" ixz="0" iyy="0.001" iyz="0" izz="0.001" />
    </inertial>
    <collision>
      <origin xyz="0.365 0 0.1" rpy="0 -0.7 0" />
      <geometry>
        <box size="0.05 0.1 0.01" />
      </geometry>
    </collision>
    <collision>
      <origin xyz="0.345 0 0.08" rpy="0 -0.0 0" />
      <geometry>
        <sphere radius="0.04" />
      </geometry>
    </collision>
    <collision>
      <origin xyz="0.25 0 0.09" rpy="0 -0.0 0" />
      <geometry>
        <sphere radius="0.04" />
      </geometry>
    </collision>
  </link>
  <joint name="front_bumper_joint" type="fixed" dont_collapse="true">
    <origin xyz="0.0 0 0" rpy="0 0 0" />
    <parent link="base_link" />
    <child link="front_bumper" />
  </joint>
  <link name="rear_bumper">
    <inertial>
      <origin xyz="0 0 0" rpy="0 0 0" />
      <mass value="0.01" />
      <inertia ixx="0.001" ixy="0" ixz="0" iyy="0.001" iyz="0" izz="0.001" />
    </inertial>
    <collision>
      <origin xyz="-0.302 0 0.112" rpy="0 0.7 0" />
      <geometry>
        <box size="0.05 0.1 0.01" />
      </geometry>
    </collision>
    <collision>
      <origin xyz="-0.285 0 0.08" rpy="0 -0.0 0" />
      <geometry>
        <sphere radius="0.04" />
      </geometry>
    </collision>
    <collision>
      <origin xyz="-0.19 0 0.09" rpy="0 -0.0 0" />
      <geometry>
        <sphere radius="0.04" />
      </geometry>
    </collision>
  </link>
  <joint name="rear_bumper_joint" type="fixed" dont_collapse="true">
    <origin xyz="0.0 0 0" rpy="0 0 0" />
    <parent link="base_link" />
    <child link="rear_bumper" />
  </joint>
  <link name="FL_hip">
    <inertial>
      <origin xyz="-2.408E-03 -16.220E-03 0.239E-03" rpy="0 0 0" />
      <mass value="1.620" />
      <inertia ixx="1476.261E-06" ixy="53.160E-06" ixz="-7.425E-06" iyy="1633.309E-06" iyz="-21.032E-06" izz="1630.804E-06" />
    </inertial>
    <visual>
      <origin xyz="0 0 0" rpy="0 0 0" />
      <geometry>
        <mesh filename="../meshes/left_front_Link1.STL" />
      </geometry>
      <material name="">
        <color rgba="0.898039215686275 0.917647058823529 0.929411764705882 1" />
      </material>
    </visual>
    <collision>
      <origin xyz="0.0 0.085 0" rpy="1.571 0 0" />
      <geometry>
        <cylinder radius="0.046" length="0.12" />
      </geometry>
    </collision>
    <collision>
      <origin xyz="0.0 -0.01 0" rpy="1.571 0 0" />
      <geometry>
        <cylinder radius="0.045" length="0.06" />
      </geometry>
    </collision>
  </link>
  <joint name="FL_hip_joint" type="revolute">
    <origin xyz="0.25944 0.075113 0" rpy="0 0 0" />
    <parent link="base_link" />
    <child link="FL_hip" />
    <axis xyz="1 0 0" />
    <limit lower="-1.01" upper="1.01" effort="120.0" velocity="22.0" />
  </joint>
  <link name="FL_thigh">
    <inertial>
      <origin xyz="-3.268E-03 -31.110E-03 -53.896E-03" rpy="0 0 0" />
      <mass value="3.079" />
      <inertia ixx="29271.794E-06" ixy="337.285E-06" ixz="-1251.409E-06" iyy="26828.777E-06" iyz="5283.783E-06" izz="5121.720E-06" />
    </inertial>
    <visual>
      <origin xyz="0 0 0" rpy="0 0 0" />
      <geometry>
        <mesh filename="../meshes/left_front_Link2.STL" />
      </geometry>
      <material name="">
        <color rgba="0.898039215686275 0.917647058823529 0.929411764705882 1" />
      </material>
    </visual>
    <collision>
      <origin xyz="-0.025 -0.003 -0.12" rpy="0 0.0 0" />
      <geometry>
        <box size="0.046 0.046 0.14" />
      </geometry>
    </collision>
    <collision>
      <origin xyz="-0.022 0.00 -0.275" rpy="0 -0.75 0" />
      <geometry>
        <box size="0.017 0.05 0.06" />
      </geometry>
    </collision>
  </link>
  <joint name="FL_thigh_joint" type="revolute">
    <origin xyz="0 0.12779 0" rpy="0 0 0" />
    <parent link="FL_hip" />
    <child link="FL_thigh" />
    <axis xyz="0 1 0" />
    <limit lower="-2.34" upper="3.15" effort="120.0" velocity="22.0" />
  </joint>
  <link name="FL_calf">
    <inertial>
      <origin xyz="4.018E-03 17.411E-03 -232.283E-03" rpy="0 0 0" />
      <mass value="1.751" />
      <inertia ixx="14397.534E-06" ixy="124.726E-06" ixz="-550.242E-06" iyy="14603.730E-06" iyz="1307.539E-06" izz="1498.341E-06" />
    </inertial>
    <visual>
      <origin xyz="0 0 0" rpy="0 0 0" />
      <geometry>
        <mesh filename="../meshes/left_front_Link3.STL" />
      </geometry>
      <material name="">
        <color rgba="0.792156862745098 0.819607843137255 0.933333333333333 1" />
      </material>
    </visual>
    <collision>
      <origin xyz="0.0 0.0 -0.275" rpy="1.571 0 0" />
      <geometry>
        <cylinder radius="0.05" length="0.03" />
      </geometry>
    </collision>
    <collision>
      <origin xyz="0.02 -0.00 -0.08" rpy="0 -0.24 0" />
      <geometry>
        <box size="0.022 0.03 0.1" />
      </geometry>
    </collision>
    <collision>
      <origin xyz="0.033 -0.00 -0.17" rpy="0 -0.03 0" />
      <geometry>
        <box size="0.022 0.03 0.08" />
      </geometry>
    </collision>
    <collision>
      <origin xyz="0.027 -0.00 -0.23" rpy="0 0.2 0" />
      <geometry>
        <box size="0.028 0.04 0.04" />
      </geometry>
    </collision>
  </link>
  <joint name="FL_calf_joint" type="revolute">
    <origin xyz="0 0 -0.275" rpy="0 0 0" />
    <parent link="FL_thigh" />
    <child link="FL_calf" />
    <axis xyz="0 1 0" />
    <limit lower="-2.77" upper="-0.54" effort="180.0" velocity="14.6667" />
  </joint>
  <link name="FL_wheel">
    <inertial>
      <origin xyz="0E-03 51.080E-03 0E-03" rpy="0 0 0" />
      <mass value="0.982" />
      <inertia ixx="2435.762E-06" ixy="0E-06" ixz="0E-06" iyy="4581.589E-06" iyz="0E-06" izz="2435.762E-06" />
    </inertial>
    <visual>
      <origin xyz="0 0 0" rpy="0 0 0" />
      <geometry>
        <mesh filename="../meshes/left_front_Link4.STL" />
      </geometry>
      <material name="">
        <color rgba="0.792156862745098 0.819607843137255 0.933333333333333 1" />
      </material>
    </visual>
    <visual>
      <origin xyz="0.1 0.05 0" rpy="0 0 0" />
      <geometry>
        <sphere radius="0.05" />
      </geometry>
      <material name="">
        <color rgba="1 0 0 1" />
      </material>
    </visual>
    <collision>
      <origin xyz="0 0 0" rpy="0 0 0" />
      <geometry>
        <mesh filename="../meshes/left_front_Link4.STL" />
      </geometry>
    </collision>
  </link>
  <joint name="FL_wheel_joint" type="revolute">
    <origin xyz="0 0 -0.275" rpy="0 0 0" />
    <parent link="FL_calf" />
    <child link="FL_wheel" />
    <axis xyz="0 1 0" />
    <limit effort="24.5" velocity="114.4" lower="-inf" upper="inf" />
  </joint>
  <link name="RL_hip">
    <inertial>
      <origin xyz="3.270E-03 -16.220E-03 -0.097E-03" rpy="0 0 0" />
      <mass value="1.620" />
      <inertia ixx="1468.092E-06" ixy="-105.396E-06" ixz="-7.294E-06" iyy="1625.457E-06" iyz="-0.444E-06" izz="1631.122E-06" />
    </inertial>
    <visual>
      <origin xyz="0 0 0" rpy="0 0 0" />
      <geometry>
        <mesh filename="../meshes/left_hind_Link1.STL" />
      </geometry>
      <material name="">
        <color rgba="0.898039215686275 0.917647058823529 0.929411764705882 1" />
      </material>
    </visual>
    <collision>
      <origin xyz="0.0 0.085 0" rpy="1.571 0 0" />
      <geometry>
        <cylinder radius="0.046" length="0.12" />
      </geometry>
    </collision>
    <collision>
      <origin xyz="0.0 -0.01 0" rpy="1.571 0 0" />
      <geometry>
        <cylinder radius="0.045" length="0.06" />
      </geometry>
    </collision>
  </link>
  <joint name="RL_hip_joint" type="revolute">
    <origin xyz="-0.25944 0.075113 0" rpy="0 0 0" />
    <parent link="base_link" />
    <child link="RL_hip" />
    <axis xyz="1 0 0" />
    <limit lower="-1.01" upper="1.01" effort="120.0" velocity="22.0" />
  </joint>
  <link name="RL_thigh">
    <inertial>
      <origin xyz="-3.268E-03 -31.110E-03 -53.896E-03" rpy="0 0 0" />
      <mass value="3.079" />
      <inertia ixx="29271.794E-06" ixy="337.285E-06" ixz="-1251.409E-06" iyy="26828.777E-06" iyz="5283.783E-06" izz="5121.720E-06" />
    </inertial>
    <visual>
      <origin xyz="0 0 0" rpy="0 0 0" />
      <geometry>
        <mesh filename="../meshes/left_hind_Link2.STL" />
      </geometry>
      <material name="">
        <color rgba="0.898039215686275 0.917647058823529 0.929411764705882 1" />
      </material>
    </visual>
    <collision>
      <origin xyz="-0.025 -0.003 -0.12" rpy="0 0.0 0" />
      <geometry>
        <box size="0.046 0.046 0.14" />
      </geometry>
    </collision>
    <collision>
      <origin xyz="-0.022 0.00 -0.275" rpy="0 -0.75 0" />
      <geometry>
        <box size="0.017 0.05 0.06" />
      </geometry>
    </collision>
  </link>
  <joint name="RL_thigh_joint" type="revolute">
    <origin xyz="0 0.12779 0" rpy="0 0 0" />
    <parent link="RL_hip" />
    <child link="RL_thigh" />
    <axis xyz="0 1 0" />
    <limit lower="-1.56" upper="3.94" effort="120.0" velocity="22.0" />
  </joint>
  <link name="RL_calf">
    <inertial>
      <origin xyz="4.018E-03 17.411E-03 -232.283E-03" rpy="0 0 0" />
      <mass value="1.751" />
      <inertia ixx="14397.534E-06" ixy="124.726E-06" ixz="-550.242E-06" iyy="14603.730E-06" iyz="1307.539E-06" izz="1498.341E-06" />
    </inertial>
    <visual>
      <origin xyz="0 0 0" rpy="0 0 0" />
      <geometry>
        <mesh filename="../meshes/left_hind_Link3.STL" />
      </geometry>
      <material name="">
        <color rgba="0.792156862745098 0.819607843137255 0.933333333333333 1" />
      </material>
    </visual>
    <collision>
      <origin xyz="0.0 0.0 -0.275" rpy="1.571 0 0" />
      <geometry>
        <cylinder radius="0.05" length="0.03" />
      </geometry>
    </collision>
    <collision>
      <origin xyz="0.02 -0.00 -0.08" rpy="0 -0.24 0" />
      <geometry>
        <box size="0.022 0.03 0.1" />
      </geometry>
    </collision>
    <collision>
      <origin xyz="0.033 -0.00 -0.17" rpy="0 -0.03 0" />
      <geometry>
        <box size="0.022 0.03 0.08" />
      </geometry>
    </collision>
    <collision>
      <origin xyz="0.027 -0.00 -0.23" rpy="0 0.2 0" />
      <geometry>
        <box size="0.028 0.04 0.04" />
      </geometry>
    </collision>
  </link>
  <joint name="RL_calf_joint" type="revolute">
    <origin xyz="0 0 -0.275" rpy="0 0 0" />
    <parent link="RL_thigh" />
    <child link="RL_calf" />
    <axis xyz="0 1 0" />
    <limit lower="-2.77" upper="-0.54" effort="180.0" velocity="14.6667" />
  </joint>
  <link name="RL_wheel">
    <inertial>
      <origin xyz="0E-03 51.080E-03 0E-03" rpy="0 0 0" />
      <mass value="0.982" />
      <inertia ixx="2435.762E-06" ixy="0E-06" ixz="0E-06" iyy="4581.589E-06" iyz="0E-06" izz="2435.762E-06" />
    </inertial>
    <visual>
      <origin xyz="0 0 0" rpy="0 0 0" />
      <geometry>
        <mesh filename="../meshes/left_hind_Link4.STL" />
      </geometry>
      <material name="">
        <color rgba="0.792156862745098 0.819607843137255 0.933333333333333 1" />
      </material>
    </visual>
    <visual>
      <origin xyz="0.1 0.05 0" rpy="0 0 0" />
      <geometry>
        <sphere radius="0.05" />
      </geometry>
      <material name="">
        <color rgba="1 0 0 1" />
      </material>
    </visual>
    <collision>
      <origin xyz="0 0 0" rpy="0 0 0" />
      <geometry>
        <mesh filename="../meshes/left_hind_Link4.STL" />
      </geometry>
    </collision>
  </link>
  <joint name="RL_wheel_joint" type="revolute">
    <origin xyz="0 0 -0.275" rpy="0 0 0" />
    <parent link="RL_calf" />
    <child link="RL_wheel" />
    <axis xyz="0 1 0" />
    <limit effort="24.5" velocity="114.4" lower="-inf" upper="inf" />
  </joint>
  <link name="FR_hip">
    <inertial>
      <origin xyz="-2.465E-03 16.220E-03 0.318E-03" rpy="0 0 0" />
      <mass value="1.620" />
      <inertia ixx="1483.677E-06" ixy="-56.616E-06" ixz="-5.890E-06" iyy="1632.784E-06" iyz="25.536E-06" izz="1622.864E-06" />
    </inertial>
    <visual>
      <origin xyz="0 0 0" rpy="0 0 0" />
      <geometry>
        <mesh filename="../meshes/right_front_Link1.STL" />
      </geometry>
      <material name="">
        <color rgba="0.898039215686275 0.917647058823529 0.929411764705882 1" />
      </material>
    </visual>
    <collision>
      <origin xyz="0.0 -0.085 0" rpy="1.571 0 0" />
      <geometry>
        <cylinder radius="0.046" length="0.12" />
      </geometry>
    </collision>
    <collision>
      <origin xyz="0.0 -0.01 0" rpy="1.571 0 0" />
      <geometry>
        <cylinder radius="0.045" length="0.06" />
      </geometry>
    </collision>
  </link>
  <joint name="FR_hip_joint" type="revolute">
    <origin xyz="0.25944 -0.075113 0" rpy="0 0 0" />
    <parent link="base_link" />
    <child link="FR_hip" />
    <axis xyz="1 0 0" />
    <limit lower="-1.01" upper="1.01" effort="120.0" velocity="22.0" />
  </joint>
  <link name="FR_thigh">
    <inertial>
      <origin xyz="-3.256E-03 31.125E-03 -53.921E-03" rpy="0 0 0" />
      <mass value="3.077" />
      <inertia ixx="29255.209E-06" ixy="-334.771E-06" ixz="-1255.239E-06" iyy="26819.094E-06" iyz="-5288.175E-06" izz="5125.147E-06" />
    </inertial>
    <visual>
      <origin xyz="0 0 0" rpy="0 0 0" />
      <geometry>
        <mesh filename="../meshes/right_front_Link2.STL" />
      </geometry>
      <material name="">
        <color rgba="0.898039215686275 0.917647058823529 0.929411764705882 1" />
      </material>
    </visual>
    <collision>
      <origin xyz="-0.025 -0.003 -0.12" rpy="0 0.0 0" />
      <geometry>
        <box size="0.046 0.046 0.14" />
      </geometry>
    </collision>
    <collision>
      <origin xyz="-0.022 0.00 -0.275" rpy="0 -0.75 0" />
      <geometry>
        <box size="0.017 0.05 0.06" />
      </geometry>
    </collision>
  </link>
  <joint name="FR_thigh_joint" type="revolute">
    <origin xyz="0 -0.12779 0" rpy="0 0 0" />
    <parent link="FR_hip" />
    <child link="FR_thigh" />
    <axis xyz="0 1 0" />
    <limit lower="-2.34" upper="3.15" effort="120.0" velocity="22.0" />
  </joint>
  <link name="FR_calf">
    <inertial>
      <origin xyz="3.855E-03 -17.411E-03 -232.224E-03" rpy="0 0 0" />
      <mass value="1.750" />
      <inertia ixx="14387.884E-06" ixy="-118.281E-06" ixz="-562.776E-06" iyy="14596.939E-06" iyz="-1309.862E-06" izz="1501.193E-06" />
    </inertial>
    <visual>
      <origin xyz="0 0 0" rpy="0 0 0" />
      <geometry>
        <mesh filename="../meshes/right_front_Link3.STL" />
      </geometry>
      <material name="">
        <color rgba="0.792156862745098 0.819607843137255 0.933333333333333 1" />
      </material>
    </visual>
    <collision>
      <origin xyz="0.0 0.0 -0.275" rpy="1.571 0 0" />
      <geometry>
        <cylinder radius="0.05" length="0.03" />
      </geometry>
    </collision>
    <collision>
      <origin xyz="0.02 -0.00 -0.08" rpy="0 -0.24 0" />
      <geometry>
        <box size="0.022 0.03 0.1" />
      </geometry>
    </collision>
    <collision>
      <origin xyz="0.033 -0.00 -0.17" rpy="0 -0.03 0" />
      <geometry>
        <box size="0.022 0.03 0.08" />
      </geometry>
    </collision>
    <collision>
      <origin xyz="0.027 -0.00 -0.23" rpy="0 0.2 0" />
      <geometry>
        <box size="0.028 0.04 0.04" />
      </geometry>
    </collision>
  </link>
  <joint name="FR_calf_joint" type="revolute">
    <origin xyz="0 0 -0.275" rpy="0 0 0" />
    <parent link="FR_thigh" />
    <child link="FR_calf" />
    <axis xyz="0 1 0" />
    <limit lower="-2.77" upper="-0.54" effort="180.0" velocity="14.6667" />
  </joint>
  <link name="FR_wheel">
    <inertial>
      <origin xyz="0E-03 -51.080E-03 0E-03" rpy="0 0 0" />
      <mass value="0.982" />
      <inertia ixx="2435.762E-06" ixy="0E-06" ixz="0E-06" iyy="4581.589E-06" iyz="0E-06" izz="2435.762E-06" />
    </inertial>
    <visual>
      <origin xyz="0 0 0" rpy="0 0 0" />
      <geometry>
        <mesh filename="../meshes/right_front_Link4.STL" />
      </geometry>
      <material name="">
        <color rgba="0.792156862745098 0.819607843137255 0.933333333333333 1" />
      </material>
    </visual>
    <visual>
      <origin xyz="0.1 -0.05 0" rpy="0 0 0" />
      <geometry>
        <sphere radius="0.05" />
      </geometry>
      <material name="">
        <color rgba="1 0 0 1" />
      </material>
    </visual>
    <collision>
      <origin xyz="0 0 0" rpy="0 0 0" />
      <geometry>
        <mesh filename="../meshes/right_front_Link4.STL" />
      </geometry>
    </collision>
  </link>
  <joint name="FR_wheel_joint" type="revolute">
    <origin xyz="0 0 -0.275" rpy="0 0 0" />
    <parent link="FR_calf" />
    <child link="FR_wheel" />
    <axis xyz="0 1 0" />
    <limit effort="24.5" velocity="114.4" lower="-inf" upper="inf" />
  </joint>
  <link name="RR_hip">
    <inertial>
      <origin xyz="3.270E-03 16.220E-03 -0.037E-03" rpy="0 0 0" />
      <mass value="1.620" />
      <inertia ixx="1464.949E-06" ixy="105.396E-06" ixz="-9.437E-06" iyy="1625.469E-06" iyz="4.282E-06" izz="1634.276E-06" />
    </inertial>
    <visual>
      <origin xyz="0 0 0" rpy="0 0 0" />
      <geometry>
        <mesh filename="../meshes/right_hind_Link1.STL" />
      </geometry>
      <material name="">
        <color rgba="0.898039215686275 0.917647058823529 0.929411764705882 1" />
      </material>
    </visual>
    <collision>
      <origin xyz="0.0 -0.085 0" rpy="1.571 0 0" />
      <geometry>
        <cylinder radius="0.046" length="0.12" />
      </geometry>
    </collision>
    <collision>
      <origin xyz="0.0 -0.01 0" rpy="1.571 0 0" />
      <geometry>
        <cylinder radius="0.045" length="0.06" />
      </geometry>
    </collision>
  </link>
  <joint name="RR_hip_joint" type="revolute">
    <origin xyz="-0.25944 -0.075113 0" rpy="0 0 0" />
    <parent link="base_link" />
    <child link="RR_hip" />
    <axis xyz="1 0 0" />
    <limit lower="-1.01" upper="1.01" effort="120.0" velocity="22.0" />
  </joint>
  <link name="RR_thigh">
    <inertial>
      <origin xyz="-3.256E-03 31.125E-03 -53.921E-03" rpy="0 0 0" />
      <mass value="3.077" />
      <inertia ixx="29255.209E-06" ixy="-334.771E-06" ixz="-1255.239E-06" iyy="26819.094E-06" iyz="-5288.175E-06" izz="5125.147E-06" />
    </inertial>
    <visual>
      <origin xyz="0 0 0" rpy="0 0 0" />
      <geometry>
        <mesh filename="../meshes/right_hind_Link2.STL" />
      </geometry>
      <material name="">
        <color rgba="0.898039215686275 0.917647058823529 0.929411764705882 1" />
      </material>
    </visual>
    <collision>
      <origin xyz="-0.025 -0.003 -0.12" rpy="0 0.0 0" />
      <geometry>
        <box size="0.046 0.046 0.14" />
      </geometry>
    </collision>
    <collision>
      <origin xyz="-0.022 0.00 -0.275" rpy="0 -0.75 0" />
      <geometry>
        <box size="0.017 0.05 0.06" />
      </geometry>
    </collision>
  </link>
  <joint name="RR_thigh_joint" type="revolute">
    <origin xyz="0 -0.12779 0" rpy="0 0 0" />
    <parent link="RR_hip" />
    <child link="RR_thigh" />
    <axis xyz="0 1 0" />
    <limit lower="-1.56" upper="3.94" effort="120.0" velocity="22.0" />
  </joint>
  <link name="RR_calf">
    <inertial>
      <origin xyz="3.855E-03 -17.411E-03 -232.224E-03" rpy="0 0 0" />
      <mass value="1.750" />
      <inertia ixx="14387.884E-06" ixy="-118.281E-06" ixz="-562.776E-06" iyy="14596.939E-06" iyz="-1309.862E-06" izz="1501.193E-06" />
    </inertial>
    <visual>
      <origin xyz="0 0 0" rpy="0 0 0" />
      <geometry>
        <mesh filename="../meshes/right_hind_Link3.STL" />
      </geometry>
      <material name="">
        <color rgba="0.792156862745098 0.819607843137255 0.933333333333333 1" />
      </material>
    </visual>
    <collision>
      <origin xyz="0.0 0.0 -0.275" rpy="1.571 0 0" />
      <geometry>
        <cylinder radius="0.05" length="0.03" />
      </geometry>
    </collision>
    <collision>
      <origin xyz="0.02 -0.00 -0.08" rpy="0 -0.24 0" />
      <geometry>
        <box size="0.022 0.03 0.1" />
      </geometry>
    </collision>
    <collision>
      <origin xyz="0.033 -0.00 -0.17" rpy="0 -0.03 0" />
      <geometry>
        <box size="0.022 0.03 0.08" />
      </geometry>
    </collision>
    <collision>
      <origin xyz="0.027 -0.00 -0.23" rpy="0 0.2 0" />
      <geometry>
        <box size="0.028 0.04 0.04" />
      </geometry>
    </collision>
  </link>
  <joint name="RR_calf_joint" type="revolute">
    <origin xyz="0 0 -0.275" rpy="0 0 0" />
    <parent link="RR_thigh" />
    <child link="RR_calf" />
    <axis xyz="0 1 0" />
    <limit lower="-2.77" upper="-0.54" effort="180.0" velocity="14.6667" />
  </joint>
  <link name="RR_wheel">
    <inertial>
      <origin xyz="0E-03 -51.080E-03 0E-03" rpy="0 0 0" />
      <mass value="0.982" />
      <inertia ixx="2435.762E-06" ixy="0E-06" ixz="0E-06" iyy="4581.589E-06" iyz="0E-06" izz="2435.762E-06" />
    </inertial>
    <visual>
      <origin xyz="0 0 0" rpy="0 0 0" />
      <geometry>
        <mesh filename="../meshes/right_hind_Link4.STL" />
      </geometry>
      <material name="">
        <color rgba="0.792156862745098 0.819607843137255 0.933333333333333 1" />
      </material>
    </visual>
    <visual>
      <origin xyz="0.1 -0.05 0" rpy="0 0 0" />
      <geometry>
        <sphere radius="0.05" />
      </geometry>
      <material name="">
        <color rgba="1 0 0 1" />
      </material>
    </visual>
    <collision>
      <origin xyz="0 0 0" rpy="0 0 0" />
      <geometry>
        <mesh filename="../meshes/right_hind_Link4.STL" />
      </geometry>
    </collision>
  </link>
  <joint name="RR_wheel_joint" type="revolute">
    <origin xyz="0 0 -0.275" rpy="0 0 0" />
    <parent link="RR_calf" />
    <child link="RR_wheel" />
    <axis xyz="0 1 0" />
    <limit effort="24.5" velocity="114.4" lower="-inf" upper="inf" />
  </joint>
  <joint name="a2w_z1_mount_joint" type="fixed" dont_collapse="true">
    <origin xyz="0 0 0" rpy="0 0 0" />
    <parent link="base_link" />
    <child link="base" />
  </joint>
  <material name="black">
    <color rgba="0.0 0.0 0.0 1.0" />
  </material>
  <material name="blue">
    <color rgba="0.0 0.0 0.8 1.0" />
  </material>
  <material name="green">
    <color rgba="0.0 0.8 0.0 1.0" />
  </material>
  <material name="grey">
    <color rgba="0.2 0.2 0.2 1.0" />
  </material>
  <material name="silver">
    <color rgba="0.9137254901960784 0.9137254901960784 0.8470588235294118 1.0" />
  </material>
  <material name="orange">
    <color rgba="0.12 0.15 0.2 1.0" />
  </material>
  <material name="brown">
    <color rgba="0.8705882352941177 0.8117647058823529 0.7647058823529411 1.0" />
  </material>
  <material name="red">
    <color rgba="0.8 0.0 0.0 1.0" />
  </material>
  <material name="white">
    <color rgba="1.0 1.0 1.0 1.0" />
  </material>
  <link name="base">
    <visual>
      <origin rpy="0 0 0" xyz="0 0 0" />
      <geometry>
        <box size="0.001 0.001 0.001" />
      </geometry>
    </visual>
  </link>
  <joint name="base_static_joint" type="fixed">
    <origin rpy="0 0 0" xyz="0.3 0 0.09" />
    <parent link="base" />
    <child link="link00" />
  </joint>
  <link name="link00">
    <visual>
      <origin rpy="1.5707963267948966 0 0" xyz="0 0 0" />
      <geometry>
        <mesh filename="../meshes/z1_Link00.dae" scale="1 1 1" />
      </geometry>
    </visual>
    <collision>
      <geometry>
        <cylinder length="0.03" radius="0.0325" />
      </geometry>
      <origin rpy="0 0 0" xyz="0 0 0.0255" />
    </collision>
    <inertial>
      <origin rpy="1.5707963267948966 0 0" xyz="-0.00334984 -0.00013615 0.02495843" />
      <mass value="0.47247481" />
      <inertia ixx="0.00037937" ixy="3.5e-07" ixz="1.037e-05" iyy="0.00041521" iyz="9.9e-07" izz="0.00053066" />
    </inertial>
  </link>
  <joint name="joint1" type="revolute">
    <origin rpy="0 0 0" xyz="0 0 0.0585" />
    <parent link="link00" />
    <child link="link01" />
    <axis xyz="0 0 1" />
    <dynamics damping="1.0" friction="1.0" />
    <limit effort="30.0" lower="-2.6179938779914944" upper="2.6179938779914944" velocity="10" />
  </joint>
  <link name="link01">
    <visual>
      <origin rpy="1.5707963267948966 0 0" xyz="0 0 0" />
      <geometry>
        <mesh filename="../meshes/z1_Link01.dae" scale="1 1 1" />
      </geometry>
    </visual>
    <inertial>
      <origin rpy="1.5707963267948966 0 0" xyz="2.47e-06 -0.00025198 0.02317169" />
      <mass value="0.67332551" />
      <inertia ixx="0.00128328" ixy="6e-08" ixz="4e-07" iyy="0.00071931" iyz="-5e-07" izz="0.00083936" />
    </inertial>
  </link>
  <joint name="joint2" type="revolute">
    <origin rpy="0 0 0" xyz="0 0 0.045" />
    <parent link="link01" />
    <child link="link02" />
    <axis xyz="0 1 0" />
    <dynamics damping="2.0" friction="2.0" />
    <limit effort="60.0" lower="0.0" upper="3.141592653589793" velocity="10" />
  </joint>
  <link name="link02">
    <visual>
      <origin rpy="1.5707963267948966 0 0" xyz="0 0 0" />
      <geometry>
        <mesh filename="../meshes/z1_Link02.dae" scale="1 1 1" />
      </geometry>
    </visual>
    <collision>
      <geometry>
        <cylinder length="0.102" radius="0.02" />
      </geometry>
      <origin rpy="1.5707963267948966 0 0" xyz="0 0 0" />
    </collision>
    <collision>
      <geometry>
        <cylinder length="0.235" radius="0.0225" />
      </geometry>
      <origin rpy="0 1.5707963267948966 0" xyz="-0.16249999999999998 0 0" />
    </collision>
    <collision>
      <geometry>
        <cylinder length="0.051" radius="0.0325" />
      </geometry>
      <origin rpy="1.5707963267948966 0 0" xyz="-0.35 0 0" />
    </collision>
    <inertial>
      <origin rpy="1.5707963267948966 0 0" xyz="-0.11012601 0.00240029 0.00158266" />
      <mass value="1.19132258" />
      <inertia ixx="0.00102138" ixy="-0.00062358" ixz="-5.13e-06" iyy="0.02429457" iyz="2.1e-06" izz="0.02466114" />
    </inertial>
  </link>
  <joint name="joint3" type="revolute">
    <origin rpy="0 0 0" xyz="-0.35 0 0" />
    <parent link="link02" />
    <child link="link03" />
    <axis xyz="0 1 0" />
    <dynamics damping="1.0" friction="1.0" />
    <limit effort="30.0" lower="-4.782202150464463" upper="0.0" velocity="10" />
  </joint>
  <link name="link03">
    <visual>
      <origin rpy="1.5707963267948966 0 0" xyz="0 0 0" />
      <geometry>
        <mesh filename="../meshes/z1_Link03.dae" scale="1 1 1" />
      </geometry>
    </visual>
    <collision>
      <geometry>
        <cylinder length="0.116" radius="0.02" />
      </geometry>
      <origin rpy="0 1.5707963267948966 0" xyz="0.128 0 0.055" />
    </collision>
    <collision>
      <geometry>
        <cylinder length="0.059" radius="0.0325" />
      </geometry>
      <origin rpy="0 1.5707963267948966 0" xyz="0.2205 0 0.055" />
    </collision>
    <inertial>
      <origin rpy="1.5707963267948966 0 0" xyz="0.10609208 -0.00541815 0.03476383" />
      <mass value="0.83940874" />
      <inertia ixx="0.00108061" ixy="8.669e-05" ixz="0.00208102" iyy="0.00954238" iyz="1.332e-05" izz="0.00886621" />
    </inertial>
  </link>
  <joint name="joint4" type="revolute">
    <origin rpy="0 0 0" xyz="0.218 0 0.057" />
    <parent link="link03" />
    <child link="link04" />
    <axis xyz="0 1 0" />
    <dynamics damping="1.0" friction="1.0" />
    <limit effort="30.0" lower="-1.7453292519943295" upper="1.5707963267948966" velocity="10" />
  </joint>
  <link name="link04">
    <visual>
      <origin rpy="1.5707963267948966 0 0" xyz="0 0 0" />
      <geometry>
        <mesh filename="../meshes/z1_Link04.dae" scale="1 1 1" />
      </geometry>
    </visual>
    <collision>
      <geometry>
        <cylinder length="0.073" radius="0.0325" />
      </geometry>
      <origin rpy="1.5707963267948966 0 0" xyz="0.0472 0 0" />
    </collision>
    <inertial>
      <origin rpy="1.5707963267948966 0 0" xyz="0.04366681 0.00364738 -0.00170192" />
      <mass value="0.56404563" />
      <inertia ixx="0.00031576" ixy="-8.13e-05" ixz="-4.091e-05" iyy="0.00092996" iyz="5.96e-06" izz="0.00097912" />
    </inertial>
  </link>
  <joint name="joint5" type="revolute">
    <origin rpy="0 0 0" xyz="0.07 0.0 0.0" />
    <parent link="link04" />
    <child link="link05" />
    <axis xyz="0 0 1" />
    <dynamics damping="1.0" friction="1.0" />
    <limit effort="30.0" lower="-1.7278759594743864" upper="1.7278759594743864" velocity="10" />
  </joint>
  <link name="link05">
    <visual>
      <origin rpy="1.5707963267948966 0 0" xyz="0 0 0" />
      <geometry>
        <mesh filename="../meshes/z1_Link05.dae" scale="1 1 1" />
      </geometry>
    </visual>
    <inertial>
      <origin rpy="1.5707963267948966 0 0" xyz="0.03121533 0.0 0.00646316" />
      <mass value="0.38938492" />
      <inertia ixx="0.00017605" ixy="-4e-07" ixz="-5.689e-05" iyy="0.00055896" iyz="1.3e-07" izz="0.0005386" />
    </inertial>
  </link>
  <joint name="joint6" type="revolute">
    <origin rpy="0 0 0" xyz="0.0492 0.0 0.0" />
    <parent link="link05" />
    <child link="link06" />
    <axis xyz="1 0 0" />
    <dynamics damping="1.0" friction="1.0" />
    <limit effort="30.0" lower="-2.792526803190927" upper="2.792526803190927" velocity="10" />
  </joint>
  <link name="link06">
    <visual>
      <origin rpy="1.5707963267948966 0 0" xyz="0 0 0" />
      <geometry>
        <mesh filename="../meshes/z1_Link06.dae" scale="1 1 1" />
      </geometry>
    </visual>
    <collision>
      <geometry>
        <cylinder length="0.051" radius="0.0325" />
      </geometry>
      <origin rpy="0 1.5707963267948966 0" xyz="0.0255 0 0" />
    </collision>
    <inertial>
      <origin rpy="1.5707963267948966 0 0" xyz="0.0241569 -0.00017355 -0.00143876" />
      <mass value="0.28875807" />
      <inertia ixx="0.00018328" ixy="-1.22e-06" ixz="-5.4e-07" iyy="0.0001475" iyz="-8e-08" izz="0.0001468" />
    </inertial>
  </link>
  <joint name="gripperStator" type="fixed">
    <origin rpy="0 0 0" xyz="0.051 0.0 0.0" />
    <parent link="link06" />
    <child link="gripperStator" />
  </joint>
  <link name="gripperStator">
    <visual>
      <origin rpy="1.5707963267948966 0 0" xyz="0 0 0" />
      <geometry>
        <mesh filename="../meshes/z1_GripperStator.dae" scale="1 1 1" />
      </geometry>
    </visual>
    <collision>
      <origin rpy="1.5707963267948966 0 0" xyz="0 0 0" />
      <geometry>
        <mesh filename="../meshes/z1_GripperStator.dae" scale="1 1 1" />
      </geometry>
    </collision>
    <inertial>
      <origin rpy="1.5707963267948966 0 0" xyz="0.04764427 -0.00035819 -0.00249162" />
      <mass value="0.52603655" />
      <inertia ixx="0.00038683" ixy="3.59e-06" ixz="-7.662e-05" iyy="0.00068614" iyz="-2.09e-06" izz="0.00066293" />
    </inertial>
  </link>
  <joint name="jointGripper" type="revolute">
    <origin rpy="0 0 0" xyz="0.049 0.0 0" />
    <parent link="gripperStator" />
    <child link="gripperMover" />
    <axis xyz="0 1 0" />
    <dynamics damping="1.0" friction="1.0" />
    <limit effort="30.0" lower="-1.5707963267948966" upper="0.0" velocity="10" />
  </joint>
  <link name="gripperMover">
    <visual>
      <origin rpy="1.5707963267948966 0 0" xyz="0 0 0" />
      <geometry>
        <mesh filename="../meshes/z1_GripperMover.dae" scale="1 1 1" />
      </geometry>
    </visual>
    <collision>
      <origin rpy="1.5707963267948966 0 0" xyz="0 0 0" />
      <geometry>
        <mesh filename="../meshes/z1_GripperMover.dae" scale="1 1 1" />
      </geometry>
    </collision>
    <inertial>
      <origin rpy="1.5707963267948966 0 0" xyz="0.01320633 0.00476708 0.00380534" />
      <mass value="0.27621302" />
      <inertia ixx="0.00017716" ixy="-1.683e-05" ixz="1.786e-05" iyy="0.00026787" iyz="-2.62e-06" izz="0.00035728" />
    </inertial>
  </link>
  <joint name="ee_gripper" type="fixed" dont_collapse="true">
    <axis xyz="1 0 0" />
    <origin rpy="0 0 0" xyz="0.135 0 0" />
    <parent link="gripperStator" />
    <child link="ee_gripper_link" />
  </joint>
  <link name="ee_gripper_link">
    <inertial>
      <mass value="0.001" />
      <inertia ixx="0.001" ixy="0" ixz="0" iyy="0.001" iyz="0" izz="0.001" />
    </inertial>
  </link>
</robot>